<?xml version="1.0" ?>
<!-- =================================================================================== -->
<!-- |    This document was autogenerated by xacro from robot.urdf.xacro               | -->
<!-- |    EDITING THIS FILE BY HAND IS NOT RECOMMENDED                                 | -->
<!-- =================================================================================== -->
<robot name="former">
  <!-- <gazebo>
        <plugin filename="gz_ros2_control-system" name="gz_ros2_control::GazeboSimROS2ControlPlugin">
            <robot_param>robot_description</robot_param>
            <parameters>$(find former_bringup)/config/controllers_former_gazebo.yaml</parameters>
        </plugin>

        <plugin filename="gz-sim-sensors-system" name="gz::sim::systems::Sensors">
            <render_engine>ogre2</render_engine>
        </plugin>

        <plugin filename="gz-sim-imu-system" name="gz::sim::systems::Imu">
        </plugin>
    </gazebo> -->
  <gazebo reference="l_wheel">
    <mu1>200</mu1>
    <mu2>200</mu2>
    <kp>10000000.0</kp>
    <kd>1.0</kd>
    <!-- <minDepth>0.001</minDepth> -->
  </gazebo>
  <gazebo reference="r_wheel">
    <mu1>200</mu1>
    <mu2>200</mu2>
    <kp>10000000.0</kp>
    <kd>1.0</kd>
    <!-- <minDepth>0.001</minDepth> -->
  </gazebo>
  <gazebo reference="f_l_caster_wheel">
    <mu1>1</mu1>
    <mu2>1</mu2>
    <kp>10000000.0</kp>
    <kd>1.0</kd>
    <!-- <minDepth>0.001</minDepth> -->
  </gazebo>
  <gazebo reference="f_r_caster_wheel">
    <mu1>1</mu1>
    <mu2>1</mu2>
    <kp>10000000.0</kp>
    <kd>1.0</kd>
    <!-- <minDepth>0.001</minDepth> -->
  </gazebo>
  <gazebo reference="r_l_caster_wheel">
    <mu1>1</mu1>
    <mu2>1</mu2>
    <kp>10000000.0</kp>
    <kd>1.0</kd>
    <!-- <minDepth>0.001</minDepth> -->
  </gazebo>
  <gazebo reference="r_r_caster_wheel">
    <mu1>1</mu1>
    <mu2>1</mu2>
    <kp>10000000.0</kp>
    <kd>1.0</kd>
    <!-- <minDepth>0.001</minDepth> -->
  </gazebo>
  <gazebo reference="base_footprint">
    <self_collide>0</self_collide>
  </gazebo>
  <!-- <gazebo reference="laser_link">
        <sensor name="laser_link" type="gpu_lidar">
            <topic>scan</topic>
            <update_rate>15</update_rate>
            <alwaysOn>1</alwaysOn>
            <visualize>true</visualize>

            <lidar>
                <scan>
                    <horizontal>
                        <samples>640</samples>
                        <resolution>1</resolution>
                        <min_angle>${-110/180*pi}</min_angle>
                        <max_angle>${110/180*pi}</max_angle>
                    </horizontal>
                    <vertical>
                        <samples>1</samples>
                        <resolution>0.01</resolution>
                        <min_angle>0</min_angle>
                        <max_angle>0</max_angle>
                    </vertical>
                </scan>
                <range>
                    <min>0.08</min>
                    <max>15.0</max>
                    <resolution>0.01</resolution>
                </range>
                <noise>
                    <type>gaussian</type>
                    <mean>0.0</mean>
                    <stddev>0.02</stddev>
                </noise>
            </lidar>
        </sensor>
    </gazebo>

    <gazebo reference="imu_link">
        <sensor name="imu" type="imu">
            <always_on>1</always_on>
            <update_rate>100</update_rate>
            <visualize>true</visualize>
            <topic>imu</topic>
            <enable_metrics>true</enable_metrics>
        </sensor>
    </gazebo>
<gazebo reference="laser_link">
        <sensor name="laser_link" type="gpu_lidar">
            <topic>scan</topic>
            <update_rate>15</update_rate>
            <alwaysOn>1</alwaysOn>
            <visualize>true</visualize>

            <lidar>
                <scan>
                    <horizontal>
                        <samples>640</samples>
                        <resolution>1</resolution>
                        <min_angle>${-110/180*pi}</min_angle>
                        <max_angle>${110/180*pi}</max_angle>
                    </horizontal>
                    <vertical>
                        <samples>1</samples>
                        <resolution>0.01</resolution>
                        <min_angle>0</min_angle>
                        <max_angle>0</max_angle>
                    </vertical>
                </scan>
                <range>
                    <min>0.08</min>
                    <max>15.0</max>
                    <resolution>0.01</resolution>
                </range>
                <noise>
                    <type>gaussian</type>
                    <mean>0.0</mean>
                    <stddev>0.02</stddev>
                </noise>
            </lidar>
        </sensor>
    </gazebo>

    <gazebo reference="imu_link">
        <sensor name="imu" type="imu">
            <always_on>1</always_on>
            <update_rate>100</update_rate>
            <visualize>true</visualize>
            <topic>imu</topic>
            <enable_metrics>true</enable_metrics>
        </sensor>
    </gazebo>

    <gazebo reference="camera_link">
        <sensor name="rgbd_camera" type="rgbd_camera">
            <always_on>1</always_on>
            <update_rate>30</update_rate>
            <visualize>true</visualize>
            <topic>camera</topic>
            <enable_metrics>true</enable_metrics>
            <camera>
                <horizontal_fov>1.047</horizontal_fov>
                <image>
                    <width>640</width>
                    <height>480</height>
                </image>
                <clip>
                    <near>0.1</near>
                    <far>100</far>
                </clip>
            </camera>
            <noise>
                <type>gaussian</type>
                <mean>0.0</mean>
                <stddev>0.02</stddev>
            </noise>
        </sensor>
    </gazebo>
    <gazebo reference="camera_link">
        <sensor name="rgbd_camera" type="rgbd_camera">
            <always_on>1</always_on>
            <update_rate>30</update_rate>
            <visualize>true</visualize>
            <topic>camera</topic>
            <enable_metrics>true</enable_metrics>
            <camera>
                <horizontal_fov>1.047</horizontal_fov>
                <image>
                    <width>640</width>
                    <height>480</height>
                </image>
                <clip>
                    <near>0.1</near>
                    <far>100</far>
                </clip>
            </camera>
            <noise>
                <type>gaussian</type>
                <mean>0.0</mean>
                <stddev>0.02</stddev>
            </noise>
        </sensor>
    </gazebo> -->
  <material name="aluminum">
    <color rgba="0.5 0.5 0.5 1"/>
  </material>
  <material name="plastic">
    <color rgba="0.1 0.1 0.1 1"/>
  </material>
  <link name="base_footprint"/>
  <link name="base_link">
    <visual>
      <origin rpy="0 0 0" xyz="0 0 0"/>
      <geometry>
        <mesh filename="package://former_description/meshes/visual/base_link.dae" scale="1 1 1"/>
      </geometry>
    </visual>
    <collision>
      <origin rpy="0 0 0" xyz="0 0 0"/>
      <geometry>
        <mesh filename="package://former_description/meshes/collision/base_link.stl" scale="1 1 1"/>
      </geometry>
    </collision>
    <inertial>
      <origin rpy="0 0 0" xyz="0.000 0.000 0.096"/>
      <mass value="32.571233"/>
      <inertia ixx="0.639569" ixy="0.000014" ixz="0.000423" iyy="0.635798" iyz="0.000003" izz="0.798308"/>
    </inertial>
  </link>
  <joint name="base_link_fixed_joint" type="fixed">
    <parent link="base_footprint"/>
    <child link="base_link"/>
    <origin rpy="0 0 0" xyz="0 0 0.0845"/>
  </joint>
  <link name="l_wheel_mount">
    <visual>
      <origin rpy="0 0 1.5707963267948966" xyz="0 0 0"/>
      <geometry>
        <mesh filename="package://former_description/meshes/visual/main_wheel_mount.dae" scale="1 1 1"/>
      </geometry>
    </visual>
    <collision>
      <origin rpy="0 0 1.5707963267948966" xyz="0 0 0"/>
      <geometry>
        <mesh filename="package://former_description/meshes/collision/main_wheel_mount.stl" scale="1 1 1"/>
      </geometry>
    </collision>
    <inertial>
      <origin rpy="0 0 1.5707963267948966" xyz="0.026 0.000 0.000"/>
      <mass value="0.007885"/>
      <inertia ixx="0.000000" ixy="0.000000" ixz="0.000000" iyy="0.000002" iyz="0.000000" izz="0.000002"/>
    </inertial>
  </link>
  <joint name="l_wheel_mount_fixed" type="fixed">
    <parent link="base_link"/>
    <child link="l_wheel_mount"/>
    <origin rpy="0 0 0" xyz="0 0.0711 0"/>
  </joint>
  <link name="l_wheel">
    <visual>
      <origin rpy="0 0 1.5707963267948966" xyz="0 0 0"/>
      <geometry>
        <mesh filename="package://former_description/meshes/visual/main_wheel.dae" scale="1 1 1"/>
      </geometry>
    </visual>
    <collision>
      <!-- <origin xyz="0 ${dir*0.025} 0" rpy="${dir*pi/2} 0 0"/> -->
      <origin rpy="0 0 1.5707963267948966" xyz="0 0 0"/>
      <geometry>
        <!-- <cylinder radius="0.0845" length="0.05"/> -->
        <mesh filename="package://former_description/meshes/collision/main_wheel.stl" scale="1 1 1"/>
      </geometry>
    </collision>
    <inertial>
      <!-- <origin xyz="0 ${dir*0.025} 0" rpy="${dir*pi/2} 0 0"/> -->
      <origin rpy="0 0 0" xyz="0.000 0.031 0.000"/>
      <mass value="0.843041"/>
      <!-- <xacro:cylinder_inertia m="0.843041" r="0.0845" h="0.05"/> -->
      <inertia ixx="0.002632" ixy="0.000000" ixz="0.000000" iyy="0.001536" iyz="0.000000" izz="0.001536"/>
    </inertial>
  </link>
  <joint name="l_wheel_joint" type="continuous">
    <parent link="l_wheel_mount"/>
    <child link="l_wheel"/>
    <axis xyz="0 1 0"/>
    <origin rpy="0 0 0" xyz="0 0.051 0"/>
  </joint>
  <link name="r_wheel_mount">
    <visual>
      <origin rpy="0 0 -1.5707963267948966" xyz="0 0 0"/>
      <geometry>
        <mesh filename="package://former_description/meshes/visual/main_wheel_mount.dae" scale="1 1 1"/>
      </geometry>
    </visual>
    <collision>
      <origin rpy="0 0 -1.5707963267948966" xyz="0 0 0"/>
      <geometry>
        <mesh filename="package://former_description/meshes/collision/main_wheel_mount.stl" scale="1 1 1"/>
      </geometry>
    </collision>
    <inertial>
      <origin rpy="0 0 -1.5707963267948966" xyz="0.026 0.000 0.000"/>
      <mass value="0.007885"/>
      <inertia ixx="0.000000" ixy="0.000000" ixz="0.000000" iyy="0.000002" iyz="0.000000" izz="0.000002"/>
    </inertial>
  </link>
  <joint name="r_wheel_mount_fixed" type="fixed">
    <parent link="base_link"/>
    <child link="r_wheel_mount"/>
    <origin rpy="0 0 0" xyz="0 -0.0711 0"/>
  </joint>
  <link name="r_wheel">
    <visual>
      <origin rpy="0 0 -1.5707963267948966" xyz="0 0 0"/>
      <geometry>
        <mesh filename="package://former_description/meshes/visual/main_wheel.dae" scale="1 1 1"/>
      </geometry>
    </visual>
    <collision>
      <!-- <origin xyz="0 ${dir*0.025} 0" rpy="${dir*pi/2} 0 0"/> -->
      <origin rpy="0 0 -1.5707963267948966" xyz="0 0 0"/>
      <geometry>
        <!-- <cylinder radius="0.0845" length="0.05"/> -->
        <mesh filename="package://former_description/meshes/collision/main_wheel.stl" scale="1 1 1"/>
      </geometry>
    </collision>
    <inertial>
      <!-- <origin xyz="0 ${dir*0.025} 0" rpy="${dir*pi/2} 0 0"/> -->
      <origin rpy="0 0 0" xyz="0.000 -0.031 0.000"/>
      <mass value="0.843041"/>
      <!-- <xacro:cylinder_inertia m="0.843041" r="0.0845" h="0.05"/> -->
      <inertia ixx="0.002632" ixy="0.000000" ixz="0.000000" iyy="0.001536" iyz="0.000000" izz="0.001536"/>
    </inertial>
  </link>
  <joint name="r_wheel_joint" type="continuous">
    <parent link="r_wheel_mount"/>
    <child link="r_wheel"/>
    <axis xyz="0 1 0"/>
    <origin rpy="0 0 0" xyz="0 -0.051 0"/>
  </joint>
  <link name="f_l_caster_mount">
    <visual>
      <origin rpy="0 0 0" xyz="0 0 0"/>
      <geometry>
        <mesh filename="package://former_description/meshes/visual/caster_mount.dae" scale="1 1 1"/>
      </geometry>
    </visual>
    <collision>
      <origin rpy="0 0 0" xyz="0 0 0"/>
      <geometry>
        <mesh filename="package://former_description/meshes/collision/caster_mount.stl" scale="1 1 1"/>
      </geometry>
    </collision>
    <inertial>
      <origin rpy="0 0 0" xyz="0.000 0.000 -0.004"/>
      <mass value="0.019629"/>
      <inertia ixx="0.000006" ixy="0.000000" ixz="0.000000" iyy="0.000005" iyz="0.000000" izz="0.000010"/>
    </inertial>
  </link>
  <joint name="f_l_caster_mount_fixed_joint" type="fixed">
    <parent link="base_link"/>
    <child link="f_l_caster_mount"/>
    <origin rpy="0 0 0" xyz="0.125 0.087 -0.0015"/>
  </joint>
  <link name="f_l_caster_rotate">
    <visual>
      <origin rpy="0 0 0" xyz="0 0 0"/>
      <geometry>
        <mesh filename="package://former_description/meshes/visual/caster_rotate.dae" scale="1 1 1"/>
      </geometry>
    </visual>
    <collision>
      <origin rpy="0 0 0" xyz="0 0 0"/>
      <geometry>
        <mesh filename="package://former_description/meshes/collision/caster_rotate.stl" scale="1 1 1"/>
      </geometry>
    </collision>
    <inertial>
      <origin rpy="0 0 0" xyz="-0.012 0.000 -0.021"/>
      <mass value="0.060591"/>
      <inertia ixx="0.000020" ixy="0.000000" ixz="-0.000004" iyy="0.000022" iyz="0.000000" izz="0.000020"/>
    </inertial>
  </link>
  <joint name="f_l_caster_rotate_joint" type="continuous">
    <parent link="f_l_caster_mount"/>
    <child link="f_l_caster_rotate"/>
    <axis xyz="0 0 1"/>
    <origin rpy="0 0 0" xyz="0 0 -0.010"/>
  </joint>
  <link name="f_l_caster_wheel">
    <visual>
      <origin rpy="0 0 0" xyz="0 0 0"/>
      <geometry>
        <mesh filename="package://former_description/meshes/visual/caster_wheel.dae" scale="1 1 1"/>
      </geometry>
    </visual>
    <collision>
      <origin rpy="0 0 0" xyz="0 0 0"/>
      <geometry>
        <mesh filename="package://former_description/meshes/collision/caster_wheel.stl" scale="1 1 1"/>
        <!-- <cylinder radius="0.0375" length="0.023"/> -->
      </geometry>
    </collision>
    <inertial>
      <origin rpy="0 0 0" xyz="0.000 0.000 0.000"/>
      <mass value="0.051842"/>
      <!-- <xacro:cylinder_inertia m="0.032222" r="0.0375" h="0.023"/> -->
      <inertia ixx="0.000013" ixy="0.000000" ixz="0.000000" iyy="0.000021" iyz="0.000000" izz="0.000013"/>
    </inertial>
  </link>
  <joint name="f_l_caster_wheel_joint" type="continuous">
    <parent link="f_l_caster_rotate"/>
    <child link="f_l_caster_wheel"/>
    <axis xyz="0 1 0"/>
    <origin rpy="0 0 0" xyz="-0.0235 0 -0.0415"/>
  </joint>
  <link name="f_r_caster_mount">
    <visual>
      <origin rpy="0 0 0" xyz="0 0 0"/>
      <geometry>
        <mesh filename="package://former_description/meshes/visual/caster_mount.dae" scale="1 1 1"/>
      </geometry>
    </visual>
    <collision>
      <origin rpy="0 0 0" xyz="0 0 0"/>
      <geometry>
        <mesh filename="package://former_description/meshes/collision/caster_mount.stl" scale="1 1 1"/>
      </geometry>
    </collision>
    <inertial>
      <origin rpy="0 0 0" xyz="0.000 0.000 -0.004"/>
      <mass value="0.019629"/>
      <inertia ixx="0.000006" ixy="0.000000" ixz="0.000000" iyy="0.000005" iyz="0.000000" izz="0.000010"/>
    </inertial>
  </link>
  <joint name="f_r_caster_mount_fixed_joint" type="fixed">
    <parent link="base_link"/>
    <child link="f_r_caster_mount"/>
    <origin rpy="0 0 0" xyz="0.125 -0.087 -0.0015"/>
  </joint>
  <link name="f_r_caster_rotate">
    <visual>
      <origin rpy="0 0 0" xyz="0 0 0"/>
      <geometry>
        <mesh filename="package://former_description/meshes/visual/caster_rotate.dae" scale="1 1 1"/>
      </geometry>
    </visual>
    <collision>
      <origin rpy="0 0 0" xyz="0 0 0"/>
      <geometry>
        <mesh filename="package://former_description/meshes/collision/caster_rotate.stl" scale="1 1 1"/>
      </geometry>
    </collision>
    <inertial>
      <origin rpy="0 0 0" xyz="-0.012 0.000 -0.021"/>
      <mass value="0.060591"/>
      <inertia ixx="0.000020" ixy="0.000000" ixz="-0.000004" iyy="0.000022" iyz="0.000000" izz="0.000020"/>
    </inertial>
  </link>
  <joint name="f_r_caster_rotate_joint" type="continuous">
    <parent link="f_r_caster_mount"/>
    <child link="f_r_caster_rotate"/>
    <axis xyz="0 0 1"/>
    <origin rpy="0 0 0" xyz="0 0 -0.010"/>
  </joint>
  <link name="f_r_caster_wheel">
    <visual>
      <origin rpy="0 0 0" xyz="0 0 0"/>
      <geometry>
        <mesh filename="package://former_description/meshes/visual/caster_wheel.dae" scale="1 1 1"/>
      </geometry>
    </visual>
    <collision>
      <origin rpy="0 0 0" xyz="0 0 0"/>
      <geometry>
        <mesh filename="package://former_description/meshes/collision/caster_wheel.stl" scale="1 1 1"/>
        <!-- <cylinder radius="0.0375" length="0.023"/> -->
      </geometry>
    </collision>
    <inertial>
      <origin rpy="0 0 0" xyz="0.000 0.000 0.000"/>
      <mass value="0.051842"/>
      <!-- <xacro:cylinder_inertia m="0.032222" r="0.0375" h="0.023"/> -->
      <inertia ixx="0.000013" ixy="0.000000" ixz="0.000000" iyy="0.000021" iyz="0.000000" izz="0.000013"/>
    </inertial>
  </link>
  <joint name="f_r_caster_wheel_joint" type="continuous">
    <parent link="f_r_caster_rotate"/>
    <child link="f_r_caster_wheel"/>
    <axis xyz="0 1 0"/>
    <origin rpy="0 0 0" xyz="-0.0235 0 -0.0415"/>
  </joint>
  <link name="r_l_caster_mount">
    <visual>
      <origin rpy="0 0 0" xyz="0 0 0"/>
      <geometry>
        <mesh filename="package://former_description/meshes/visual/caster_mount.dae" scale="1 1 1"/>
      </geometry>
    </visual>
    <collision>
      <origin rpy="0 0 0" xyz="0 0 0"/>
      <geometry>
        <mesh filename="package://former_description/meshes/collision/caster_mount.stl" scale="1 1 1"/>
      </geometry>
    </collision>
    <inertial>
      <origin rpy="0 0 0" xyz="0.000 0.000 -0.004"/>
      <mass value="0.019629"/>
      <inertia ixx="0.000006" ixy="0.000000" ixz="0.000000" iyy="0.000005" iyz="0.000000" izz="0.000010"/>
    </inertial>
  </link>
  <joint name="r_l_caster_mount_fixed_joint" type="fixed">
    <parent link="base_link"/>
    <child link="r_l_caster_mount"/>
    <origin rpy="0 0 0" xyz="-0.128 0.099 -0.0015"/>
  </joint>
  <link name="r_l_caster_rotate">
    <visual>
      <origin rpy="0 0 0" xyz="0 0 0"/>
      <geometry>
        <mesh filename="package://former_description/meshes/visual/caster_rotate.dae" scale="1 1 1"/>
      </geometry>
    </visual>
    <collision>
      <origin rpy="0 0 0" xyz="0 0 0"/>
      <geometry>
        <mesh filename="package://former_description/meshes/collision/caster_rotate.stl" scale="1 1 1"/>
      </geometry>
    </collision>
    <inertial>
      <origin rpy="0 0 0" xyz="-0.012 0.000 -0.021"/>
      <mass value="0.060591"/>
      <inertia ixx="0.000020" ixy="0.000000" ixz="-0.000004" iyy="0.000022" iyz="0.000000" izz="0.000020"/>
    </inertial>
  </link>
  <joint name="r_l_caster_rotate_joint" type="continuous">
    <parent link="r_l_caster_mount"/>
    <child link="r_l_caster_rotate"/>
    <axis xyz="0 0 1"/>
    <origin rpy="0 0 0" xyz="0 0 -0.010"/>
  </joint>
  <link name="r_l_caster_wheel">
    <visual>
      <origin rpy="0 0 0" xyz="0 0 0"/>
      <geometry>
        <mesh filename="package://former_description/meshes/visual/caster_wheel.dae" scale="1 1 1"/>
      </geometry>
    </visual>
    <collision>
      <origin rpy="0 0 0" xyz="0 0 0"/>
      <geometry>
        <mesh filename="package://former_description/meshes/collision/caster_wheel.stl" scale="1 1 1"/>
        <!-- <cylinder radius="0.0375" length="0.023"/> -->
      </geometry>
    </collision>
    <inertial>
      <origin rpy="0 0 0" xyz="0.000 0.000 0.000"/>
      <mass value="0.051842"/>
      <!-- <xacro:cylinder_inertia m="0.032222" r="0.0375" h="0.023"/> -->
      <inertia ixx="0.000013" ixy="0.000000" ixz="0.000000" iyy="0.000021" iyz="0.000000" izz="0.000013"/>
    </inertial>
  </link>
  <joint name="r_l_caster_wheel_joint" type="continuous">
    <parent link="r_l_caster_rotate"/>
    <child link="r_l_caster_wheel"/>
    <axis xyz="0 1 0"/>
    <origin rpy="0 0 0" xyz="-0.0235 0 -0.0415"/>
  </joint>
  <link name="r_r_caster_mount">
    <visual>
      <origin rpy="0 0 0" xyz="0 0 0"/>
      <geometry>
        <mesh filename="package://former_description/meshes/visual/caster_mount.dae" scale="1 1 1"/>
      </geometry>
    </visual>
    <collision>
      <origin rpy="0 0 0" xyz="0 0 0"/>
      <geometry>
        <mesh filename="package://former_description/meshes/collision/caster_mount.stl" scale="1 1 1"/>
      </geometry>
    </collision>
    <inertial>
      <origin rpy="0 0 0" xyz="0.000 0.000 -0.004"/>
      <mass value="0.019629"/>
      <inertia ixx="0.000006" ixy="0.000000" ixz="0.000000" iyy="0.000005" iyz="0.000000" izz="0.000010"/>
    </inertial>
  </link>
  <joint name="r_r_caster_mount_fixed_joint" type="fixed">
    <parent link="base_link"/>
    <child link="r_r_caster_mount"/>
    <origin rpy="0 0 0" xyz="-0.128 -0.099 -0.0015"/>
  </joint>
  <link name="r_r_caster_rotate">
    <visual>
      <origin rpy="0 0 0" xyz="0 0 0"/>
      <geometry>
        <mesh filename="package://former_description/meshes/visual/caster_rotate.dae" scale="1 1 1"/>
      </geometry>
    </visual>
    <collision>
      <origin rpy="0 0 0" xyz="0 0 0"/>
      <geometry>
        <mesh filename="package://former_description/meshes/collision/caster_rotate.stl" scale="1 1 1"/>
      </geometry>
    </collision>
    <inertial>
      <origin rpy="0 0 0" xyz="-0.012 0.000 -0.021"/>
      <mass value="0.060591"/>
      <inertia ixx="0.000020" ixy="0.000000" ixz="-0.000004" iyy="0.000022" iyz="0.000000" izz="0.000020"/>
    </inertial>
  </link>
  <joint name="r_r_caster_rotate_joint" type="continuous">
    <parent link="r_r_caster_mount"/>
    <child link="r_r_caster_rotate"/>
    <axis xyz="0 0 1"/>
    <origin rpy="0 0 0" xyz="0 0 -0.010"/>
  </joint>
  <link name="r_r_caster_wheel">
    <visual>
      <origin rpy="0 0 0" xyz="0 0 0"/>
      <geometry>
        <mesh filename="package://former_description/meshes/visual/caster_wheel.dae" scale="1 1 1"/>
      </geometry>
    </visual>
    <collision>
      <origin rpy="0 0 0" xyz="0 0 0"/>
      <geometry>
        <mesh filename="package://former_description/meshes/collision/caster_wheel.stl" scale="1 1 1"/>
        <!-- <cylinder radius="0.0375" length="0.023"/> -->
      </geometry>
    </collision>
    <inertial>
      <origin rpy="0 0 0" xyz="0.000 0.000 0.000"/>
      <mass value="0.051842"/>
      <!-- <xacro:cylinder_inertia m="0.032222" r="0.0375" h="0.023"/> -->
      <inertia ixx="0.000013" ixy="0.000000" ixz="0.000000" iyy="0.000021" iyz="0.000000" izz="0.000013"/>
    </inertial>
  </link>
  <joint name="r_r_caster_wheel_joint" type="continuous">
    <parent link="r_r_caster_rotate"/>
    <child link="r_r_caster_wheel"/>
    <axis xyz="0 1 0"/>
    <origin rpy="0 0 0" xyz="-0.0235 0 -0.0415"/>
  </joint>
  <link name="imu_sensor">
    <visual>
      <origin rpy="0 0 0" xyz="0 0 0"/>
      <geometry>
        <mesh filename="package://former_description/meshes/visual/imu.dae" scale="1 1 1"/>
      </geometry>
    </visual>
    <collision>
      <origin rpy="0 0 0" xyz="0 0 0"/>
      <geometry>
        <mesh filename="package://former_description/meshes/collision/imu.stl" scale="1 1 1"/>
      </geometry>
    </collision>
    <inertial>
      <origin rpy="0 0 0" xyz="0.0 0.0 0.0045"/>
      <mass value="0.1"/>
      <inertia ixx="2.9466666666666663e-06" ixy="0" ixz="0" iyy="2.9466666666666663e-06" iyz="0" izz="5.461333333333334e-06"/>
    </inertial>
  </link>
  <joint name="imu_sensor_fixed_joint" type="fixed">
    <parent link="base_link"/>
    <child link="imu_sensor"/>
    <origin rpy="0 0 0" xyz="0.134 0 0.0045"/>
  </joint>
  <link name="imu_link"/>
  <joint name="imu_link_fixed_joint" type="fixed">
    <parent link="imu_sensor"/>
    <child link="imu_link"/>
    <origin xyz="0.0 0.0 0.009"/>
  </joint>
  <link name="l_sonar_sensor">
    <visual>
      <origin rpy="0 0 0" xyz="0 0 0"/>
      <geometry>
        <mesh filename="package://former_description/meshes/visual/sonar_sensor.dae" scale="1 1 1"/>
      </geometry>
    </visual>
    <collision>
      <origin rpy="0 0 0" xyz="0 0 0"/>
      <geometry>
        <mesh filename="package://former_description/meshes/collision/sonar_sensor.stl" scale="1 1 1"/>
      </geometry>
    </collision>
    <inertial>
      <origin rpy="0 0 0" xyz="0.004 0.002 0.000"/>
      <mass value="0.009290"/>
      <inertia ixx="0.000001" ixy="0.000000" ixz="0.000000" iyy="0.000001" iyz="0.000000" izz="0.000001"/>
    </inertial>
  </link>
  <joint name="l_sonar_sensor_fixed" type="fixed">
    <parent link="base_link"/>
    <child link="l_sonar_sensor"/>
    <origin rpy="0 0 0" xyz="0.184 0.0968 0.084"/>
  </joint>
  <link name="r_sonar_sensor">
    <visual>
      <origin rpy="0 0 0" xyz="0 0 0"/>
      <geometry>
        <mesh filename="package://former_description/meshes/visual/sonar_sensor.dae" scale="1 1 1"/>
      </geometry>
    </visual>
    <collision>
      <origin rpy="0 0 0" xyz="0 0 0"/>
      <geometry>
        <mesh filename="package://former_description/meshes/collision/sonar_sensor.stl" scale="1 1 1"/>
      </geometry>
    </collision>
    <inertial>
      <origin rpy="0 0 0" xyz="0.004 0.002 0.000"/>
      <mass value="0.009290"/>
      <inertia ixx="0.000001" ixy="0.000000" ixz="0.000000" iyy="0.000001" iyz="0.000000" izz="0.000001"/>
    </inertial>
  </link>
  <joint name="r_sonar_sensor_fixed" type="fixed">
    <parent link="base_link"/>
    <child link="r_sonar_sensor"/>
    <origin rpy="0 0 0" xyz="0.184 -0.0968 0.084"/>
  </joint>
  <link name="lidar_mount">
    <visual>
      <origin rpy="0 0 0" xyz="0 0 0"/>
      <geometry>
        <mesh filename="package://former_description/meshes/visual/sick_tim5_lidar.dae" scale="1 1 1"/>
      </geometry>
    </visual>
    <collision>
      <origin rpy="0 0 0" xyz="0 0 0"/>
      <geometry>
        <mesh filename="package://former_description/meshes/collision/sick_tim5_lidar.stl" scale="1 1 1"/>
      </geometry>
    </collision>
    <inertial>
      <origin rpy="0 0 0" xyz="-0.002 0.000 0.036"/>
      <mass value="0.180090"/>
      <inertia ixx="0.000139" ixy="0.000000" ixz="0.000002" iyy="0.000129" iyz="0.000000" izz="0.000094"/>
    </inertial>
  </link>
  <joint name="lidar_mount_fixed_joint" type="fixed">
    <parent link="base_link"/>
    <child link="lidar_mount"/>
    <origin rpy="3.141592653589793 0 0" xyz="0.160 0 0.2275"/>
  </joint>
  <link name="laser_link"/>
  <joint name="laser_link_fixed_joint" type="fixed">
    <parent link="lidar_mount"/>
    <child link="laser_link"/>
    <origin rpy="3.141592653589793 0 0" xyz="0 0 0.060"/>
  </joint>
  <!-- camera body, with origin at bottom screw mount -->
  <joint name="camera_joint" type="fixed">
    <origin rpy="0 -0.2617993877991494 0" xyz="0.1777 0 0.06715"/>
    <parent link="base_link"/>
    <child link="camera_bottom_screw_frame"/>
  </joint>
  <link name="camera_bottom_screw_frame"/>
  <joint name="camera_link_joint" type="fixed">
    <origin rpy="0 0 0" xyz="0.010600000000000002 0.0175 0.0125"/>
    <parent link="camera_bottom_screw_frame"/>
    <child link="camera_link"/>
  </joint>
  <link name="camera_link">
    <visual>
      <!-- the mesh origin is at front plate in between the two infrared camera axes -->
      <origin rpy="1.5707963267948966 0 1.5707963267948966" xyz="0.0043 -0.0175 0"/>
      <geometry>
        <mesh filename="package://realsense2_description/meshes/d435.dae"/>
      </geometry>
    </visual>
    <collision>
      <origin rpy="0 0 0" xyz="0 -0.0175 0"/>
      <geometry>
        <box size="0.02505 0.09 0.025"/>
      </geometry>
    </collision>
    <inertial>
      <!-- The following are not reliable values, and should not be used for modeling -->
      <mass value="0.072"/>
      <origin xyz="0 0 0"/>
      <inertia ixx="0.003881243" ixy="0.0" ixz="0.0" iyy="0.000498940" iyz="0.0" izz="0.003879257"/>
    </inertial>
  </link>
  <ros2_control name="former_system" type="system">
    <!-- Real robot hardware_interface -->
    <joint name="l_wheel_joint">
      <command_interface name="velocity">
        <param name="min">-1.0</param>
        <param name="max">1.0</param>
      </command_interface>
      <state_interface name="position"/>
      <state_interface name="velocity"/>
    </joint>
    <joint name="r_wheel_joint">
      <command_interface name="velocity">
        <param name="min">-1.0</param>
        <param name="max">1.0</param>
      </command_interface>
      <state_interface name="position"/>
      <state_interface name="velocity"/>
    </joint>
  </ros2_control>
</robot>
