<sdf version='1.7'>
  <model name='former'>
    <link name='base_footprint'>
      <inertial>
        <pose>0.001784 3.9e-05 0.180433 0 -0 0</pose>
        <mass>33.0362</mass>
        <inertia>
          <ixx>0.64795</ixx>
          <ixy>-0.000223398</ixy>
          <ixz>-0.000878101</ixz>
          <iyy>0.650388</iyy>
          <iyz>2.10397e-05</iyz>
          <izz>0.813857</izz>
        </inertia>
      </inertial>
      <collision name='base_footprint_fixed_joint_lump__base_link_collision'>
        <pose>0 0 0.0845 0 -0 0</pose>
        <geometry>
          <mesh>
            <scale>1 1 1</scale>
            <uri>model://former_description/meshes/collision/base_link.stl</uri>
          </mesh>
        </geometry>
      </collision>
      <collision name='base_footprint_fixed_joint_lump__camera_link_collision_1'>
        <pose>0.184704 0 0.166468 0 -0.261799 0</pose>
        <geometry>
          <box>
            <size>0.02505 0.09 0.025</size>
          </box>
        </geometry>
      </collision>
      <collision name='base_footprint_fixed_joint_lump__f_l_caster_mount_collision_2'>
        <pose>0.125 0.087 0.083 0 -0 0</pose>
        <geometry>
          <mesh>
            <scale>1 1 1</scale>
            <uri>model://former_description/meshes/collision/caster_mount.stl</uri>
          </mesh>
        </geometry>
      </collision>
      <collision name='base_footprint_fixed_joint_lump__f_r_caster_mount_collision_3'>
        <pose>0.125 -0.087 0.083 0 -0 0</pose>
        <geometry>
          <mesh>
            <scale>1 1 1</scale>
            <uri>model://former_description/meshes/collision/caster_mount.stl</uri>
          </mesh>
        </geometry>
      </collision>
      <collision name='base_footprint_fixed_joint_lump__imu_sensor_collision_4'>
        <pose>0.134 0 0.089 0 -0 0</pose>
        <geometry>
          <mesh>
            <scale>1 1 1</scale>
            <uri>model://former_description/meshes/collision/imu.stl</uri>
          </mesh>
        </geometry>
      </collision>
      <collision name='base_footprint_fixed_joint_lump__l_sonar_sensor_collision_5'>
        <pose>0.184 0.0968 0.1685 0 -0 0</pose>
        <geometry>
          <mesh>
            <scale>1 1 1</scale>
            <uri>model://former_description/meshes/collision/sonar_sensor.stl</uri>
          </mesh>
        </geometry>
      </collision>
      <collision name='base_footprint_fixed_joint_lump__l_wheel_mount_collision_6'>
        <pose>0 0.0711 0.0845 0 -0 1.5708</pose>
        <geometry>
          <mesh>
            <scale>1 1 1</scale>
            <uri>model://former_description/meshes/collision/main_wheel_mount.stl</uri>
          </mesh>
        </geometry>
      </collision>
      <collision name='base_footprint_fixed_joint_lump__lidar_mount_collision_7'>
        <pose>0.16 0 0.312 3.14159 -0 0</pose>
        <geometry>
          <mesh>
            <scale>1 1 1</scale>
            <uri>model://former_description/meshes/collision/sick_tim5_lidar.stl</uri>
          </mesh>
        </geometry>
      </collision>
      <collision name='base_footprint_fixed_joint_lump__r_l_caster_mount_collision_8'>
        <pose>-0.128 0.099 0.083 0 -0 0</pose>
        <geometry>
          <mesh>
            <scale>1 1 1</scale>
            <uri>model://former_description/meshes/collision/caster_mount.stl</uri>
          </mesh>
        </geometry>
      </collision>
      <collision name='base_footprint_fixed_joint_lump__r_r_caster_mount_collision_9'>
        <pose>-0.128 -0.099 0.083 0 -0 0</pose>
        <geometry>
          <mesh>
            <scale>1 1 1</scale>
            <uri>model://former_description/meshes/collision/caster_mount.stl</uri>
          </mesh>
        </geometry>
      </collision>
      <collision name='base_footprint_fixed_joint_lump__r_sonar_sensor_collision_10'>
        <pose>0.184 -0.0968 0.1685 0 -0 0</pose>
        <geometry>
          <mesh>
            <scale>1 1 1</scale>
            <uri>model://former_description/meshes/collision/sonar_sensor.stl</uri>
          </mesh>
        </geometry>
      </collision>
      <collision name='base_footprint_fixed_joint_lump__r_wheel_mount_collision_11'>
        <pose>0 -0.0711 0.0845 0 0 -1.5708</pose>
        <geometry>
          <mesh>
            <scale>1 1 1</scale>
            <uri>model://former_description/meshes/collision/main_wheel_mount.stl</uri>
          </mesh>
        </geometry>
      </collision>
      <visual name='base_footprint_fixed_joint_lump__base_link_visual'>
        <pose>0 0 0.0845 0 -0 0</pose>
        <geometry>
          <mesh>
            <scale>1 1 1</scale>
            <uri>model://former_description/meshes/visual/base_link.dae</uri>
          </mesh>
        </geometry>
      </visual>
      <visual name='base_footprint_fixed_joint_lump__camera_link_visual_1'>
        <pose>0.188857 0 0.16758 1.309 -0 1.5708</pose>
        <geometry>
          <mesh>
            <scale>1 1 1</scale>
            <uri>model://realsense2_description/meshes/d435.dae</uri>
          </mesh>
        </geometry>
      </visual>
      <visual name='base_footprint_fixed_joint_lump__f_l_caster_mount_visual_2'>
        <pose>0.125 0.087 0.083 0 -0 0</pose>
        <geometry>
          <mesh>
            <scale>1 1 1</scale>
            <uri>model://former_description/meshes/visual/caster_mount.dae</uri>
          </mesh>
        </geometry>
      </visual>
      <visual name='base_footprint_fixed_joint_lump__f_r_caster_mount_visual_3'>
        <pose>0.125 -0.087 0.083 0 -0 0</pose>
        <geometry>
          <mesh>
            <scale>1 1 1</scale>
            <uri>model://former_description/meshes/visual/caster_mount.dae</uri>
          </mesh>
        </geometry>
      </visual>
      <visual name='base_footprint_fixed_joint_lump__imu_sensor_visual_4'>
        <pose>0.134 0 0.089 0 -0 0</pose>
        <geometry>
          <mesh>
            <scale>1 1 1</scale>
            <uri>model://former_description/meshes/visual/imu.dae</uri>
          </mesh>
        </geometry>
      </visual>
      <visual name='base_footprint_fixed_joint_lump__l_sonar_sensor_visual_5'>
        <pose>0.184 0.0968 0.1685 0 -0 0</pose>
        <geometry>
          <mesh>
            <scale>1 1 1</scale>
            <uri>model://former_description/meshes/visual/sonar_sensor.dae</uri>
          </mesh>
        </geometry>
      </visual>
      <visual name='base_footprint_fixed_joint_lump__l_wheel_mount_visual_6'>
        <pose>0 0.0711 0.0845 0 -0 1.5708</pose>
        <geometry>
          <mesh>
            <scale>1 1 1</scale>
            <uri>model://former_description/meshes/visual/main_wheel_mount.dae</uri>
          </mesh>
        </geometry>
      </visual>
      <visual name='base_footprint_fixed_joint_lump__lidar_mount_visual_7'>
        <pose>0.16 0 0.312 3.14159 -0 0</pose>
        <geometry>
          <mesh>
            <scale>1 1 1</scale>
            <uri>model://former_description/meshes/visual/sick_tim5_lidar.dae</uri>
          </mesh>
        </geometry>
      </visual>
      <visual name='base_footprint_fixed_joint_lump__r_l_caster_mount_visual_8'>
        <pose>-0.128 0.099 0.083 0 -0 0</pose>
        <geometry>
          <mesh>
            <scale>1 1 1</scale>
            <uri>model://former_description/meshes/visual/caster_mount.dae</uri>
          </mesh>
        </geometry>
      </visual>
      <visual name='base_footprint_fixed_joint_lump__r_r_caster_mount_visual_9'>
        <pose>-0.128 -0.099 0.083 0 -0 0</pose>
        <geometry>
          <mesh>
            <scale>1 1 1</scale>
            <uri>model://former_description/meshes/visual/caster_mount.dae</uri>
          </mesh>
        </geometry>
      </visual>
      <visual name='base_footprint_fixed_joint_lump__r_sonar_sensor_visual_10'>
        <pose>0.184 -0.0968 0.1685 0 -0 0</pose>
        <geometry>
          <mesh>
            <scale>1 1 1</scale>
            <uri>model://former_description/meshes/visual/sonar_sensor.dae</uri>
          </mesh>
        </geometry>
      </visual>
      <visual name='base_footprint_fixed_joint_lump__r_wheel_mount_visual_11'>
        <pose>0 -0.0711 0.0845 0 0 -1.5708</pose>
        <geometry>
          <mesh>
            <scale>1 1 1</scale>
            <uri>model://former_description/meshes/visual/main_wheel_mount.dae</uri>
          </mesh>
        </geometry>
      </visual>
      <self_collide>0</self_collide>
    </link>
    <joint name='f_l_caster_rotate_joint' type='revolute'>
      <pose relative_to='base_footprint'>0.125 0.087 0.073 0 -0 0</pose>
      <parent>base_footprint</parent>
      <child>f_l_caster_rotate</child>
      <axis>
        <xyz>0 0 1</xyz>
        <limit>
          <lower>-1e+16</lower>
          <upper>1e+16</upper>
        </limit>
        <dynamics>
          <spring_reference>0</spring_reference>
          <spring_stiffness>0</spring_stiffness>
        </dynamics>
      </axis>
    </joint>
    <link name='f_l_caster_rotate'>
      <pose relative_to='f_l_caster_rotate_joint'>0 0 0 0 -0 0</pose>
      <inertial>
        <pose>-0.012 0 -0.021 0 -0 0</pose>
        <mass>0.060591</mass>
        <inertia>
          <ixx>2e-05</ixx>
          <ixy>0</ixy>
          <ixz>-4e-06</ixz>
          <iyy>2.2e-05</iyy>
          <iyz>0</iyz>
          <izz>2e-05</izz>
        </inertia>
      </inertial>
      <collision name='f_l_caster_rotate_collision'>
        <pose>0 0 0 0 -0 0</pose>
        <geometry>
          <mesh>
            <scale>1 1 1</scale>
            <uri>model://former_description/meshes/collision/caster_rotate.stl</uri>
          </mesh>
        </geometry>
      </collision>
      <visual name='f_l_caster_rotate_visual'>
        <pose>0 0 0 0 -0 0</pose>
        <geometry>
          <mesh>
            <scale>1 1 1</scale>
            <uri>model://former_description/meshes/visual/caster_rotate.dae</uri>
          </mesh>
        </geometry>
      </visual>
    </link>
    <joint name='f_l_caster_wheel_joint' type='revolute'>
      <pose relative_to='f_l_caster_rotate'>-0.0235 0 -0.0415 0 -0 0</pose>
      <parent>f_l_caster_rotate</parent>
      <child>f_l_caster_wheel</child>
      <axis>
        <xyz>0 1 0</xyz>
        <limit>
          <lower>-1e+16</lower>
          <upper>1e+16</upper>
        </limit>
        <dynamics>
          <spring_reference>0</spring_reference>
          <spring_stiffness>0</spring_stiffness>
        </dynamics>
      </axis>
    </joint>
    <link name='f_l_caster_wheel'>
      <pose relative_to='f_l_caster_wheel_joint'>0 0 0 0 -0 0</pose>
      <inertial>
        <pose>0 0 0 0 -0 0</pose>
        <mass>0.051842</mass>
        <inertia>
          <ixx>1.3e-05</ixx>
          <ixy>0</ixy>
          <ixz>0</ixz>
          <iyy>2.1e-05</iyy>
          <iyz>0</iyz>
          <izz>1.3e-05</izz>
        </inertia>
      </inertial>
      <collision name='f_l_caster_wheel_collision'>
        <pose>0 0 0 0 -0 0</pose>
        <geometry>
          <mesh>
            <scale>1 1 1</scale>
            <uri>model://former_description/meshes/collision/caster_wheel.stl</uri>
          </mesh>
        </geometry>
        <surface>
          <contact>
            <ode>
              <kp>1e+07</kp>
              <kd>1</kd>
            </ode>
          </contact>
          <friction>
            <ode>
              <mu>1</mu>
              <mu2>1</mu2>
            </ode>
          </friction>
        </surface>
      </collision>
      <visual name='f_l_caster_wheel_visual'>
        <pose>0 0 0 0 -0 0</pose>
        <geometry>
          <mesh>
            <scale>1 1 1</scale>
            <uri>model://former_description/meshes/visual/caster_wheel.dae</uri>
          </mesh>
        </geometry>
      </visual>
    </link>
    <joint name='f_r_caster_rotate_joint' type='revolute'>
      <pose relative_to='base_footprint'>0.125 -0.087 0.073 0 -0 0</pose>
      <parent>base_footprint</parent>
      <child>f_r_caster_rotate</child>
      <axis>
        <xyz>0 0 1</xyz>
        <limit>
          <lower>-1e+16</lower>
          <upper>1e+16</upper>
        </limit>
        <dynamics>
          <spring_reference>0</spring_reference>
          <spring_stiffness>0</spring_stiffness>
        </dynamics>
      </axis>
    </joint>
    <link name='f_r_caster_rotate'>
      <pose relative_to='f_r_caster_rotate_joint'>0 0 0 0 -0 0</pose>
      <inertial>
        <pose>-0.012 0 -0.021 0 -0 0</pose>
        <mass>0.060591</mass>
        <inertia>
          <ixx>2e-05</ixx>
          <ixy>0</ixy>
          <ixz>-4e-06</ixz>
          <iyy>2.2e-05</iyy>
          <iyz>0</iyz>
          <izz>2e-05</izz>
        </inertia>
      </inertial>
      <collision name='f_r_caster_rotate_collision'>
        <pose>0 0 0 0 -0 0</pose>
        <geometry>
          <mesh>
            <scale>1 1 1</scale>
            <uri>model://former_description/meshes/collision/caster_rotate.stl</uri>
          </mesh>
        </geometry>
      </collision>
      <visual name='f_r_caster_rotate_visual'>
        <pose>0 0 0 0 -0 0</pose>
        <geometry>
          <mesh>
            <scale>1 1 1</scale>
            <uri>model://former_description/meshes/visual/caster_rotate.dae</uri>
          </mesh>
        </geometry>
      </visual>
    </link>
    <joint name='f_r_caster_wheel_joint' type='revolute'>
      <pose relative_to='f_r_caster_rotate'>-0.0235 0 -0.0415 0 -0 0</pose>
      <parent>f_r_caster_rotate</parent>
      <child>f_r_caster_wheel</child>
      <axis>
        <xyz>0 1 0</xyz>
        <limit>
          <lower>-1e+16</lower>
          <upper>1e+16</upper>
        </limit>
        <dynamics>
          <spring_reference>0</spring_reference>
          <spring_stiffness>0</spring_stiffness>
        </dynamics>
      </axis>
    </joint>
    <link name='f_r_caster_wheel'>
      <pose relative_to='f_r_caster_wheel_joint'>0 0 0 0 -0 0</pose>
      <inertial>
        <pose>0 0 0 0 -0 0</pose>
        <mass>0.051842</mass>
        <inertia>
          <ixx>1.3e-05</ixx>
          <ixy>0</ixy>
          <ixz>0</ixz>
          <iyy>2.1e-05</iyy>
          <iyz>0</iyz>
          <izz>1.3e-05</izz>
        </inertia>
      </inertial>
      <collision name='f_r_caster_wheel_collision'>
        <pose>0 0 0 0 -0 0</pose>
        <geometry>
          <mesh>
            <scale>1 1 1</scale>
            <uri>model://former_description/meshes/collision/caster_wheel.stl</uri>
          </mesh>
        </geometry>
        <surface>
          <contact>
            <ode>
              <kp>1e+07</kp>
              <kd>1</kd>
            </ode>
          </contact>
          <friction>
            <ode>
              <mu>1</mu>
              <mu2>1</mu2>
            </ode>
          </friction>
        </surface>
      </collision>
      <visual name='f_r_caster_wheel_visual'>
        <pose>0 0 0 0 -0 0</pose>
        <geometry>
          <mesh>
            <scale>1 1 1</scale>
            <uri>model://former_description/meshes/visual/caster_wheel.dae</uri>
          </mesh>
        </geometry>
      </visual>
    </link>
    <joint name='l_wheel_joint' type='revolute'>
      <pose relative_to='base_footprint'>0 0.1221 0.0845 0 -0 0</pose>
      <parent>base_footprint</parent>
      <child>l_wheel</child>
      <axis>
        <xyz>0 1 0</xyz>
        <limit>
          <lower>-1e+16</lower>
          <upper>1e+16</upper>
        </limit>
        <dynamics>
          <spring_reference>0</spring_reference>
          <spring_stiffness>0</spring_stiffness>
        </dynamics>
      </axis>
    </joint>
    <link name='l_wheel'>
      <pose relative_to='l_wheel_joint'>0 0 0 0 -0 0</pose>
      <inertial>
        <pose>0 0.031 0 0 -0 0</pose>
        <mass>0.843041</mass>
        <inertia>
          <ixx>0.002632</ixx>
          <ixy>0</ixy>
          <ixz>0</ixz>
          <iyy>0.001536</iyy>
          <iyz>0</iyz>
          <izz>0.001536</izz>
        </inertia>
      </inertial>
      <collision name='l_wheel_collision'>
        <pose>0 0 0 0 -0 1.5708</pose>
        <geometry>
          <mesh>
            <scale>1 1 1</scale>
            <uri>model://former_description/meshes/collision/main_wheel.stl</uri>
          </mesh>
        </geometry>
        <surface>
          <contact>
            <ode>
              <kp>1e+07</kp>
              <kd>1</kd>
            </ode>
          </contact>
          <friction>
            <ode>
              <mu>200</mu>
              <mu2>200</mu2>
            </ode>
          </friction>
        </surface>
      </collision>
      <visual name='l_wheel_visual'>
        <pose>0 0 0 0 -0 1.5708</pose>
        <geometry>
          <mesh>
            <scale>1 1 1</scale>
            <uri>model://former_description/meshes/visual/main_wheel.dae</uri>
          </mesh>
        </geometry>
      </visual>
    </link>
    <joint name='r_l_caster_rotate_joint' type='revolute'>
      <pose relative_to='base_footprint'>-0.128 0.099 0.073 0 -0 0</pose>
      <parent>base_footprint</parent>
      <child>r_l_caster_rotate</child>
      <axis>
        <xyz>0 0 1</xyz>
        <limit>
          <lower>-1e+16</lower>
          <upper>1e+16</upper>
        </limit>
        <dynamics>
          <spring_reference>0</spring_reference>
          <spring_stiffness>0</spring_stiffness>
        </dynamics>
      </axis>
    </joint>
    <link name='r_l_caster_rotate'>
      <pose relative_to='r_l_caster_rotate_joint'>0 0 0 0 -0 0</pose>
      <inertial>
        <pose>-0.012 0 -0.021 0 -0 0</pose>
        <mass>0.060591</mass>
        <inertia>
          <ixx>2e-05</ixx>
          <ixy>0</ixy>
          <ixz>-4e-06</ixz>
          <iyy>2.2e-05</iyy>
          <iyz>0</iyz>
          <izz>2e-05</izz>
        </inertia>
      </inertial>
      <collision name='r_l_caster_rotate_collision'>
        <pose>0 0 0 0 -0 0</pose>
        <geometry>
          <mesh>
            <scale>1 1 1</scale>
            <uri>model://former_description/meshes/collision/caster_rotate.stl</uri>
          </mesh>
        </geometry>
      </collision>
      <visual name='r_l_caster_rotate_visual'>
        <pose>0 0 0 0 -0 0</pose>
        <geometry>
          <mesh>
            <scale>1 1 1</scale>
            <uri>model://former_description/meshes/visual/caster_rotate.dae</uri>
          </mesh>
        </geometry>
      </visual>
    </link>
    <joint name='r_l_caster_wheel_joint' type='revolute'>
      <pose relative_to='r_l_caster_rotate'>-0.0235 0 -0.0415 0 -0 0</pose>
      <parent>r_l_caster_rotate</parent>
      <child>r_l_caster_wheel</child>
      <axis>
        <xyz>0 1 0</xyz>
        <limit>
          <lower>-1e+16</lower>
          <upper>1e+16</upper>
        </limit>
        <dynamics>
          <spring_reference>0</spring_reference>
          <spring_stiffness>0</spring_stiffness>
        </dynamics>
      </axis>
    </joint>
    <link name='r_l_caster_wheel'>
      <pose relative_to='r_l_caster_wheel_joint'>0 0 0 0 -0 0</pose>
      <inertial>
        <pose>0 0 0 0 -0 0</pose>
        <mass>0.051842</mass>
        <inertia>
          <ixx>1.3e-05</ixx>
          <ixy>0</ixy>
          <ixz>0</ixz>
          <iyy>2.1e-05</iyy>
          <iyz>0</iyz>
          <izz>1.3e-05</izz>
        </inertia>
      </inertial>
      <collision name='r_l_caster_wheel_collision'>
        <pose>0 0 0 0 -0 0</pose>
        <geometry>
          <mesh>
            <scale>1 1 1</scale>
            <uri>model://former_description/meshes/collision/caster_wheel.stl</uri>
          </mesh>
        </geometry>
        <surface>
          <contact>
            <ode>
              <kp>1e+07</kp>
              <kd>1</kd>
            </ode>
          </contact>
          <friction>
            <ode>
              <mu>1</mu>
              <mu2>1</mu2>
            </ode>
          </friction>
        </surface>
      </collision>
      <visual name='r_l_caster_wheel_visual'>
        <pose>0 0 0 0 -0 0</pose>
        <geometry>
          <mesh>
            <scale>1 1 1</scale>
            <uri>model://former_description/meshes/visual/caster_wheel.dae</uri>
          </mesh>
        </geometry>
      </visual>
    </link>
    <joint name='r_r_caster_rotate_joint' type='revolute'>
      <pose relative_to='base_footprint'>-0.128 -0.099 0.073 0 -0 0</pose>
      <parent>base_footprint</parent>
      <child>r_r_caster_rotate</child>
      <axis>
        <xyz>0 0 1</xyz>
        <limit>
          <lower>-1e+16</lower>
          <upper>1e+16</upper>
        </limit>
        <dynamics>
          <spring_reference>0</spring_reference>
          <spring_stiffness>0</spring_stiffness>
        </dynamics>
      </axis>
    </joint>
    <link name='r_r_caster_rotate'>
      <pose relative_to='r_r_caster_rotate_joint'>0 0 0 0 -0 0</pose>
      <inertial>
        <pose>-0.012 0 -0.021 0 -0 0</pose>
        <mass>0.060591</mass>
        <inertia>
          <ixx>2e-05</ixx>
          <ixy>0</ixy>
          <ixz>-4e-06</ixz>
          <iyy>2.2e-05</iyy>
          <iyz>0</iyz>
          <izz>2e-05</izz>
        </inertia>
      </inertial>
      <collision name='r_r_caster_rotate_collision'>
        <pose>0 0 0 0 -0 0</pose>
        <geometry>
          <mesh>
            <scale>1 1 1</scale>
            <uri>model://former_description/meshes/collision/caster_rotate.stl</uri>
          </mesh>
        </geometry>
      </collision>
      <visual name='r_r_caster_rotate_visual'>
        <pose>0 0 0 0 -0 0</pose>
        <geometry>
          <mesh>
            <scale>1 1 1</scale>
            <uri>model://former_description/meshes/visual/caster_rotate.dae</uri>
          </mesh>
        </geometry>
      </visual>
    </link>
    <joint name='r_r_caster_wheel_joint' type='revolute'>
      <pose relative_to='r_r_caster_rotate'>-0.0235 0 -0.0415 0 -0 0</pose>
      <parent>r_r_caster_rotate</parent>
      <child>r_r_caster_wheel</child>
      <axis>
        <xyz>0 1 0</xyz>
        <limit>
          <lower>-1e+16</lower>
          <upper>1e+16</upper>
        </limit>
        <dynamics>
          <spring_reference>0</spring_reference>
          <spring_stiffness>0</spring_stiffness>
        </dynamics>
      </axis>
    </joint>
    <link name='r_r_caster_wheel'>
      <pose relative_to='r_r_caster_wheel_joint'>0 0 0 0 -0 0</pose>
      <inertial>
        <pose>0 0 0 0 -0 0</pose>
        <mass>0.051842</mass>
        <inertia>
          <ixx>1.3e-05</ixx>
          <ixy>0</ixy>
          <ixz>0</ixz>
          <iyy>2.1e-05</iyy>
          <iyz>0</iyz>
          <izz>1.3e-05</izz>
        </inertia>
      </inertial>
      <collision name='r_r_caster_wheel_collision'>
        <pose>0 0 0 0 -0 0</pose>
        <geometry>
          <mesh>
            <scale>1 1 1</scale>
            <uri>model://former_description/meshes/collision/caster_wheel.stl</uri>
          </mesh>
        </geometry>
        <surface>
          <contact>
            <ode>
              <kp>1e+07</kp>
              <kd>1</kd>
            </ode>
          </contact>
          <friction>
            <ode>
              <mu>1</mu>
              <mu2>1</mu2>
            </ode>
          </friction>
        </surface>
      </collision>
      <visual name='r_r_caster_wheel_visual'>
        <pose>0 0 0 0 -0 0</pose>
        <geometry>
          <mesh>
            <scale>1 1 1</scale>
            <uri>model://former_description/meshes/visual/caster_wheel.dae</uri>
          </mesh>
        </geometry>
      </visual>
    </link>
    <joint name='r_wheel_joint' type='revolute'>
      <pose relative_to='base_footprint'>0 -0.1221 0.0845 0 -0 0</pose>
      <parent>base_footprint</parent>
      <child>r_wheel</child>
      <axis>
        <xyz>0 1 0</xyz>
        <limit>
          <lower>-1e+16</lower>
          <upper>1e+16</upper>
        </limit>
        <dynamics>
          <spring_reference>0</spring_reference>
          <spring_stiffness>0</spring_stiffness>
        </dynamics>
      </axis>
    </joint>
    <link name='r_wheel'>
      <pose relative_to='r_wheel_joint'>0 0 0 0 -0 0</pose>
      <inertial>
        <pose>0 -0.031 0 0 -0 0</pose>
        <mass>0.843041</mass>
        <inertia>
          <ixx>0.002632</ixx>
          <ixy>0</ixy>
          <ixz>0</ixz>
          <iyy>0.001536</iyy>
          <iyz>0</iyz>
          <izz>0.001536</izz>
        </inertia>
      </inertial>
      <collision name='r_wheel_collision'>
        <pose>0 0 0 0 0 -1.5708</pose>
        <geometry>
          <mesh>
            <scale>1 1 1</scale>
            <uri>model://former_description/meshes/collision/main_wheel.stl</uri>
          </mesh>
        </geometry>
        <surface>
          <contact>
            <ode>
              <kp>1e+07</kp>
              <kd>1</kd>
            </ode>
          </contact>
          <friction>
            <ode>
              <mu>200</mu>
              <mu2>200</mu2>
            </ode>
          </friction>
        </surface>
      </collision>
      <visual name='r_wheel_visual'>
        <pose>0 0 0 0 0 -1.5708</pose>
        <geometry>
          <mesh>
            <scale>1 1 1</scale>
            <uri>model://former_description/meshes/visual/main_wheel.dae</uri>
          </mesh>
        </geometry>
      </visual>
    </link>
  </model>
</sdf>
